<?xml version="1.0" encoding="utf-8"?>
<!-- =================================================================================== -->
<!-- |    This document was autogenerated by xacro from dogbot.xacro                   | -->
<!-- |    EDITING THIS FILE BY HAND IS NOT RECOMMENDED                                 | -->
<!-- =================================================================================== -->
<robot name="dogbot">
  <!-- ===================================================================================
     |    DogBot v4 URDF                                                               |
     |    2019 React Robotics Ltd
     |
     |    Licence: CC-BY, https://creativecommons.org/licenses/by/4.0/legalcode
     |    Author:  Nic Greenway, nic@reactrobotics.com
     |
     |    Note: some details of mass and inertia in this file are estimates, 
     |    as DogBot design is still undergoing refinements, and values will vary
     |    with individual DogBot specification (e.g. battery configuration, on-board
     |    processor, etc.)
     =================================================================================== -->
  <!-- ixx="0.005834583" iyy="0.005834583" izz="0.00044" -->
  <!-- ixx="0.00160765" iyy="0.0016075" izz="0.00044"-->
  <material name="Red">
    <color rgba="0.8 0.0 0.0 1.0"/>
  </material>
  <material name="blue">
    <color rgba="0 0 0.8 1"/>
  </material>
  <material name="black">
    <color rgba="0 0 0 1"/>
  </material>
  <material name="white">
    <color rgba="1 1 1 1"/>
  </material>
  <material name="dogbotred">
    <color rgba="1 0 0 1"/>
  </material>
  <material name="dogbotgray">
    <color rgba="0.7 0.7 0.7 1"/>
  </material>
  <!-- start the robot links -->
  <link name="base_link">
  </link>
  <link name="body">
    <visual>
      <origin rpy="-1.57079632679 0 0" xyz="0 0 0"/>
      <geometry>
        <mesh filename="package://dogbot_description/meshes/body.dae" scale="1.0 1.0 1.0"/>
      </geometry>
    </visual>
    <collision>
      <origin rpy="0 0 0" xyz="0 0 0"/>
      <geometry>
        <box size="0.177 0.433 0.105"/>
      </geometry>
    </collision>
    <collision>
      <origin rpy="1.57079632679 0 0" xyz="0.0885 0 0"/>
      <geometry>
        <cylinder length="0.433" radius="0.0525"/>
      </geometry>
    </collision>
    <collision>
      <origin rpy="1.57079632679 0 0" xyz="-0.0885 0 0"/>
      <geometry>
        <cylinder length="0.433" radius="0.0525"/>
      </geometry>
    </collision>
    <collision>
      <origin rpy="0 0 0" xyz="0 0.2825 0"/>
      <geometry>
        <box size="0.035 0.132 0.105"/>
      </geometry>
    </collision>
    <collision>
      <origin rpy="0 0 0" xyz="0 -0.2825 0"/>
      <geometry>
        <box size="0.035 0.132 0.105"/>
      </geometry>
    </collision>
    <collision>
      <origin rpy="0 0 0" xyz="0 0.3975 0"/>
      <geometry>
        <box size="0.177 0.08 0.105"/>
      </geometry>
    </collision>
    <collision>
      <origin rpy="1.57079632679 0 0" xyz="0.0885 0.3975 0"/>
      <geometry>
        <cylinder length="0.08" radius="0.0525"/>
      </geometry>
    </collision>
    <collision>
      <origin rpy="1.57079632679 0 0" xyz="-0.0885 0.3975 0"/>
      <geometry>
        <cylinder length="0.08" radius="0.0525"/>
      </geometry>
    </collision>
    <collision>
      <origin rpy="0 0 0" xyz="0 -0.3975 0"/>
      <geometry>
        <box size="0.177 0.08 0.105"/>
      </geometry>
    </collision>
    <collision>
      <origin rpy="1.57079632679 0 0" xyz="0.0885 -0.3975 0"/>
      <geometry>
        <cylinder length="0.08" radius="0.0525"/>
      </geometry>
    </collision>
    <collision>
      <origin rpy="1.57079632679 0 0" xyz="-0.0885 -0.3975 0"/>
      <geometry>
        <cylinder length="0.08" radius="0.0525"/>
      </geometry>
    </collision>
    <inertial>
      <mass value="9.3"/>
      <origin rpy="0 0 0" xyz="0 0 0"/>
      <inertia ixx="0.41" ixy="0" ixz="0" iyy="0.091" iyz="0" izz="0.482"/>
    </inertial>
  </link>
  <joint name="shoulder_adduction_joint" type="revolute">
    <parent link="body"/>
    <child link="shoulder_adduction_link"/>
    <origin rpy="0 0 0" xyz="0 -0.453 0.005"/>
    <axis xyz="0 0 1"/>
    <limit effort="300" lower="-6.28" upper="6.28" velocity="6"/>
    <!--  <dynamics damping="50" friction="1"/> -->
  </joint>
  <link name="shoulder_adduction_link">
    <visual>
      <origin rpy="3.14159 0 0" xyz="0 0 0"/>
      <geometry>
        <cylinder length="0.12" radius="0.04"/>
      </geometry>
      <material name="Gray"/>
      <!-- <material name="Black" /> -->
    </visual>
    <collision>
      <origin rpy="3.14159 0 0" xyz="0 0 0"/>
      <geometry>
        <cylinder length="0.12" radius="0.04"/>
        <!-- r=0.04 l=0.120 -->
      </geometry>
    </collision>
    <inertial>
      <mass value="0.5"/>
      <origin rpy="3.14159 0 0" xyz="0 0 0"/>
      <inertia ixx="0.0008" ixy="0.0" ixz="0.0" iyy="0.0008" iyz="0.0" izz="0.0004"/>
    </inertial>
  </link>
  <gazebo reference="shoulder_adduction_link">
    <material>Gazebo/Gray</material>
  </gazebo>
  <!-- VALORI DA INSERIRE PER MODIFICARE I TENSORI DI INERZIA -->
  <joint name="shoulder_flexion_joint" type="revolute">
    <parent link="shoulder_adduction_link"/>
    <child link="shoulder_flexion_link"/>
    <origin rpy="0 0 0" xyz="0 0 -0.097"/>
    <axis xyz="1 0 0"/>
    <limit effort="300" lower="-6.28" upper="6.28" velocity="6"/>
    <!-- <dynamics damping="50" friction="1"/> -->
  </joint>
  <link name="shoulder_flexion_link">
    <visual>
      <origin rpy="1.570795 0 0" xyz="0 0 0"/>
      <geometry>
        <sphere radius="0.04"/>
        <!-- length="${shoulder_flexion_len}"/> -->
      </geometry>
      <material name="dogbotred"/>
    </visual>
    <collision>
      <origin rpy="1.570795 0 0" xyz="0 0 0"/>
      <geometry>
        <sphere radius="0.04"/>
        <!-- length="${shoulder_flexion_len}"/> -->
      </geometry>
    </collision>
    <inertial>
      <mass value="0.5"/>
      <origin rpy="1.570795 0 0" xyz="0 0 0"/>
      <inertia ixx="0.00032" ixy="0.0" ixz="0.0" iyy="0.00032" iyz="0.0" izz="0.00032"/>
    </inertial>
  </link>
  <gazebo reference="shoulder_flexion_link">
    <!-- <material>Gazebo/Red</material> -->
    <visual>
      <material>
        <ambient>0.53 0.11 0.098 1 </ambient>
        <diffuse>0.53 0.11 0.098 1</diffuse>
        <specular>0.1 0.1 0.1 1</specular>
        <emissive>0 0 0 0</emissive>
      </material>
    </visual>
  </gazebo>
  <joint name="humerus_rotation_joint" type="revolute">
    <parent link="shoulder_flexion_link"/>
    <child link="humerus_rotation_link"/>
    <origin rpy="0 0 0" xyz="0 -0.125 0"/>
    <axis xyz="0 -1 0"/>
    <limit effort="300" lower="-6.28" upper="6.28" velocity="6"/>
    <!-- <dynamics damping="50" friction="1"/> -->
  </joint>
  <link name="humerus_rotation_link">
    <visual>
      <origin rpy="1.570795 0 0" xyz="0 0 0"/>
      <geometry>
        <cylinder length="0.175" radius="0.04"/>
      </geometry>
      <material name="Gray"/>
    </visual>
    <collision>
      <origin rpy="1.570795 0 0" xyz="0 0 0"/>
      <geometry>
        <cylinder length="0.175" radius="0.04"/>
        <!--r=0.04 l=0.175 -->
      </geometry>
    </collision>
    <inertial>
      <mass value="0.5"/>
      <origin rpy="1.570795 0 0" xyz="0 0 0"/>
      <inertia ixx="0.00147604166667" ixy="0.0" ixz="0.0" iyy="0.00147604166667" iyz="0.0" izz="0.0004"/>
    </inertial>
  </link>
  <gazebo reference="humerus_rotation_link">
    <material>Gazebo/Gray</material>
  </gazebo>
  <joint name="elbow_flexion_joint" type="revolute">
    <parent link="humerus_rotation_link"/>
    <child link="elbow_flexion_link"/>
    <origin rpy="0 0 0" xyz="0 -0.125 0"/>
    <axis xyz="1 0 0"/>
    <limit effort="300" lower="-6.28" upper="6.28" velocity="6"/>
    <!-- <dynamics damping="50" friction="1"/> -->
  </joint>
  <link name="elbow_flexion_link">
    <visual>
      <origin rpy="1.570795 0 0" xyz="0 0 0"/>
      <geometry>
        <sphere radius="0.04"/>
      </geometry>
      <material name="Red"/>
    </visual>
    <collision>
      <origin rpy="1.570795 0 0" xyz="0 0 0"/>
      <!-- rotazione rispetto all'asse y di 90 gradi-->
      <geometry>
        <sphere radius="0.04"/>
        <!-- length="${elbow_flexion_len}"/> -->
      </geometry>
    </collision>
    <inertial>
      <mass value="0.5"/>
      <origin rpy="1.570795 0 0" xyz="0 0 0"/>
      <inertia ixx="0.00032" ixy="0.0" ixz="0.0" iyy="0.00032" iyz="0.0" izz="0.00032"/>
    </inertial>
  </link>
  <gazebo reference="elbow_flexion_link">
    <!-- <material>Gazebo/Red</material> -->
    <visual>
      <material>
        <ambient>0.53 0.11 0.098 1 </ambient>
        <diffuse>0.53 0.11 0.098 1</diffuse>
        <specular>0.1 0.1 0.1 1</specular>
        <emissive>0 0 0 0</emissive>
      </material>
    </visual>
  </gazebo>
  <link name="wrist_rotation_link">
    <visual>
      <origin rpy="0 0 0" xyz="0 0 0"/>
      <geometry>
        <cylinder length="0.175" radius="0.04"/>
      </geometry>
      <material name="Gray"/>
    </visual>
    <collision>
      <origin rpy="0 0 0" xyz="0 0 0"/>
      <geometry>
        <cylinder length="0.175" radius="0.04"/>
        <!--r=0.04 l=0.175 -->
      </geometry>
    </collision>
    <inertial>
      <mass value="0.5"/>
      <origin rpy="0 0 0" xyz="0 0 0"/>
      <inertia ixx="0.00147604166667" ixy="0.0" ixz="0.0" iyy="0.00147604166667" iyz="0.0" izz="0.0004"/>
    </inertial>
  </link>
  <gazebo reference="wrist_rotation_link">
    <material>Gazebo/Gray</material>
  </gazebo>
  <joint name="wrist_rotation_joint" type="revolute">
    <parent link="elbow_flexion_link"/>
    <child link="wrist_rotation_link"/>
    <origin rpy="0 0 0" xyz="0 0 0.125"/>
    <axis xyz="0 0 1"/>
    <limit effort="300" lower="-6.28" upper="6.28" velocity="6"/>
     --&gt;
    
    <!-- <dynamics damping="50" friction="1"/> -->
  </joint>
  <link name="wrist_flexion_link">
    <visual>
      <origin rpy="1.570795 0 0" xyz="0 0 0"/>
      <geometry>
        <cylinder length="0.087" radius="0.04"/>
      </geometry>
      <material name="Red"/>
    </visual>
    <collision>
      <origin rpy="1.570795 0 0" xyz="0 0 0"/>
      <!-- rotazione rispetto all'asse y di 90 gradi-->
      <geometry>
        <cylinder length="0.087" radius="0.04"/>
        <!--r=0.04 l=0.087 -->
      </geometry>
    </collision>
    <inertial>
      <mass value="0.5"/>
      <origin rpy="1.570795 0 0" xyz="0 0 0"/>
      <inertia ixx="0.000515375" ixy="0.0" ixz="0.0" iyy="0.000515375" iyz="0.0" izz="0.0004"/>
    </inertial>
  </link>
  <gazebo reference="wrist_flexion_link">
    <!-- <material>Gazebo/Red</material> -->
    <visual>
      <material>
        <ambient>0.53 0.11 0.098 1 </ambient>
        <diffuse>0.53 0.11 0.098 1</diffuse>
        <specular>0.1 0.1 0.1 1</specular>
        <emissive>0 0 0 0</emissive>
      </material>
    </visual>
  </gazebo>
  <joint name="wrist_flexion_joint" type="revolute">
    <parent link="wrist_rotation_link"/>
    <child link="wrist_flexion_link"/>
    <origin rpy="0 0 0" xyz="0 0 0.125"/>
    <axis xyz="1 0 0"/>
    <limit effort="300" lower="-6.28" upper="6.28" velocity="6"/>
    <!-- <dynamics damping="50" friction="1"/> -->
  </joint>
  <transmission name="shoulder_adduction_transmition">
    <type>transmission_interface/SimpleTransmission</type>
    <joint name="shoulder_adduction_joint">
      <hardwareInterface>hardware_interface/EffortJointInterface</hardwareInterface>
    </joint>
    <actuator name="shoulder_adduction_motor">
      <hardwareInterface>hardware_interface/EffortJointInterface</hardwareInterface>
      <mechanicalReduction>1</mechanicalReduction>
    </actuator>
  </transmission>
  <transmission name="shoulder_flexion_transmition">
    <type>transmission_interface/SimpleTransmission</type>
    <joint name="shoulder_flexion_joint">
      <hardwareInterface>hardware_interface/EffortJointInterface</hardwareInterface>
    </joint>
    <actuator name="shoulder_flexion_motor">
      <hardwareInterface>hardware_interface/EffortJointInterface</hardwareInterface>
      <mechanicalReduction>1</mechanicalReduction>
    </actuator>
  </transmission>
  <transmission name="humerus_rotation_transmition">
    <type>transmission_interface/SimpleTransmission</type>
    <joint name="humerus_rotation_joint">
      <hardwareInterface>hardware_interface/EffortJointInterface</hardwareInterface>
    </joint>
    <actuator name="humerus_rotation_motor">
      <hardwareInterface>hardware_interface/EffortJointInterface</hardwareInterface>
      <mechanicalReduction>1</mechanicalReduction>
    </actuator>
  </transmission>
  <transmission name="elbow_flexion_transmition">
    <type>transmission_interface/SimpleTransmission</type>
    <joint name="elbow_flexion_joint">
      <hardwareInterface>hardware_interface/EffortJointInterface</hardwareInterface>
    </joint>
    <actuator name="elbow_flexion_motor">
      <hardwareInterface>hardware_interface/EffortJointInterface</hardwareInterface>
      <mechanicalReduction>1</mechanicalReduction>
    </actuator>
  </transmission>
  <transmission name="wrist_rotation_transmition">
    <type>transmission_interface/SimpleTransmission</type>
    <joint name="wrist_rotation_joint">
      <hardwareInterface>hardware_interface/EffortJointInterface</hardwareInterface>
    </joint>
    <actuator name="wrist_rotation_motor">
      <hardwareInterface>hardware_interface/EffortJointInterface</hardwareInterface>
      <mechanicalReduction>1</mechanicalReduction>
    </actuator>
  </transmission>
  <transmission name="wrist_flexion_transmition">
    <type>transmission_interface/SimpleTransmission</type>
    <joint name="wrist_flexion_joint">
      <hardwareInterface>hardware_interface/EffortJointInterface</hardwareInterface>
    </joint>
    <actuator name="wrist_flexion_motor">
      <hardwareInterface>hardware_interface/EffortJointInterface</hardwareInterface>
      <mechanicalReduction>1</mechanicalReduction>
    </actuator>
  </transmission>
  <!--link name="first_gripper_link" >

    <visual>
      <origin xyz="0 0 0" rpy="0 0 0" />
      <geometry>
	      <box size="0.1 0.022 0.022"/>

      </geometry>
      <material name="Gray" />
    </visual>

    <collision>
      <origin xyz="0 0 0" rpy="0 0 0" /> 
      <geometry>
            <box size="0.1 0.022 0.022"/> 
      </geometry>
    </collision>
		<xacro:inertial_matrix mass="0.05"/>
   </link>

	<gazebo reference="first_gripper_link">
    <material>Gazebo/Gray</material>
  </gazebo>

	<joint name="first_gripper_joint" type="fixed">
    <parent link="wrist_flexion_link"/>
    <child link="first_gripper_link"/>
    <origin xyz="-0.051 0 0.047" rpy="0 ${M_PI/3} 0" />
   </joint> 
   
	 <link name="second_gripper_link" >

    <visual>
      <origin xyz="0 0 0" rpy="0 0 0" />
      <geometry>
	      <box size="0.1 0.022 0.022"/>

      </geometry>
      <material name="Gray" />
    </visual>

    <collision>
      <origin xyz="0 0 0" rpy="0 0 0" /> 
      <geometry>
            <box size="0.1 0.022 0.022"/> 
      </geometry>
    </collision>
		<xacro:inertial_matrix mass="0.05"/>
   </link>

	<gazebo reference="second_gripper_link">
    <material>Gazebo/Gray</material>
  </gazebo>

	<joint name="second_gripper_joint" type="fixed">
    <parent link="wrist_flexion_link"/>
    <child link="second_gripper_link"/>
    <origin xyz="0.051 0 0.047" rpy="0 -${M_PI/3} 0" />
   </joint-->
  <!--
	 <link name="tray_link" >

    <visual>
      <origin xyz="0 0 0" rpy="0 0 0" />
      <geometry>
	      <cylinder radius="0.2" length="0.005"/>

      </geometry>
      <material name="White" />
    </visual>

    <collision>
      <origin xyz="0 0 0" rpy="0 0 0" /> 
      <geometry>
            <cylinder radius="0.1" length="0.005"/> 
      </geometry>
    </collision>
		<xacro:inertial_matrix mass="0.150"/>
   </link>

	<gazebo reference="tray_link">
    <material>Gazebo/White</material>
  </gazebo>

	<joint name="tray_joint" type="fixed">
    <parent link="wrist_flexion_link"/>
    <child link="tray_link"/>
    <origin xyz="-0.045 0 0.022" rpy="0 ${M_PI/1.3} 0" />
   </joint> 
 -->
  <joint name="base_joint" type="fixed">
    <axis rpy="0 0 0" xyz="0 0 0"/>
    <parent link="base_link"/>
    <child link="body"/>
  </joint>
  <link name="bodytext">
    <visual>
      <origin rpy="-1.57079632679 0 0" xyz="0 0 0"/>
      <geometry>
        <mesh filename="package://dogbot_description/meshes/bodyTEXT.dae" scale="1.0 1.0 1.0"/>
      </geometry>
    </visual>
    <inertial>
      <mass value="0.001"/>
      <origin rpy="0 0 0" xyz="0 0 0"/>
      <inertia ixx="1.66666666667e-10" ixy="0.0" ixz="0.0" iyy="1.66666666667e-10" iyz="0.0" izz="1.66666666667e-10"/>
    </inertial>
  </link>
  <joint name="bodytext_joint" type="fixed">
    <parent link="body"/>
    <child link="bodytext"/>
  </joint>
  <gazebo reference="body">
    <mu1 value="200.0"/>
    <mu2 value="100.0"/>
    <kp value="1000000"/>
    <kd value="1.0"/>
    <sensor name="base_link_contactsensor_sensor" type="contact">
      <always_on>true</always_on>
      <contact>
        <collision>base_link_fixed_joint_lump__body_collision_8</collision>
      </contact>
      <plugin filename="libgazebo_ros_bumper.so" name="body_plugin">
        <bumperTopicName>base_link_contactsensor_state</bumperTopicName>
        <!--<frameName>${prefix}_${suffix}_foot</frameName>-->
        <frameName>world</frameName>
      </plugin>
    </sensor>
    <sensor name="base_link_contactsensor_sensor2" type="contact">
      <always_on>true</always_on>
      <contact>
        <collision>base_link_fixed_joint_lump__body_collision_9</collision>
      </contact>
      <plugin filename="libgazebo_ros_bumper.so" name="body_plugin2">
        <bumperTopicName>base_link_contactsensor_state2</bumperTopicName>
        <!--<frameName>${prefix}_${suffix}_foot</frameName>-->
        <frameName>world</frameName>
      </plugin>
    </sensor>
    <sensor name="base_link_contactsensor_sensor3" type="contact">
      <always_on>true</always_on>
      <contact>
        <collision>base_link_fixed_joint_lump__body_collision_10</collision>
      </contact>
      <plugin filename="libgazebo_ros_bumper.so" name="body_plugin3">
        <bumperTopicName>base_link_contactsensor_state3</bumperTopicName>
        <!--<frameName>${prefix}_${suffix}_foot</frameName>-->
        <frameName>world</frameName>
      </plugin>
    </sensor>
  </gazebo>
  <link name="back_left_hip">
    <visual>
      <origin rpy="-1.57079632679 -3.14159265359 0" xyz="0 0 0"/>
      <geometry>
        <mesh filename="package://dogbot_description/meshes/hip.dae" scale="1.0 1.0 1.0"/>
      </geometry>
    </visual>
    <collision>
      <origin rpy="0 1.57079632679 0" xyz="-0.02 0 0"/>
      <geometry>
        <cylinder length="0.08" radius="0.0525"/>
      </geometry>
    </collision>
    <inertial>
      <mass value="0.836"/>
      <origin rpy="0 0 0" xyz="-0.0074 0 0"/>
      <inertia ixx="0.00213" ixy="0" ixz="0" iyy="0.00147" iyz="0" izz="0.00172"/>
    </inertial>
  </link>
  <!-- roll joint connects the hip to the body -->
  <joint name="back_left_roll_joint" type="revolute">
    <axis rpy="0 0 0" xyz="0 -1 0"/>
    <parent link="body"/>
    <child link="back_left_hip"/>
    <origin rpy="0 0 0" xyz="-0.088 -0.2875 0"/>
    <limit effort="60" lower="-1.7453" upper="1.7453" velocity="6.0"/>
  </joint>
  <link name="back_left_upperleg">
    <visual>
      <origin rpy="-1.57079632679 0 -3.14159265359" xyz="0 0 0"/>
      <geometry>
        <mesh filename="package://dogbot_description/meshes/LegUpper_withCover.dae" scale="1.0 1.0 1.0"/>
      </geometry>
    </visual>
    <collision>
      <origin rpy="0 1.57079632679 0" xyz="-0.03 0 0"/>
      <geometry>
        <cylinder length="0.13" radius="0.0525"/>
      </geometry>
    </collision>
    <collision>
      <origin rpy="0 0 0" xyz="0 0 -0.135"/>
      <geometry>
        <cylinder length="0.27" radius="0.033"/>
      </geometry>
    </collision>
    <collision>
      <origin rpy="0 0 0" xyz="0 0 -0.135"/>
      <geometry>
        <box size="0.025 0.084 0.27"/>
      </geometry>
    </collision>
    <collision>
      <origin rpy="0 0 0" xyz="-0.046 0 -0.126"/>
      <geometry>
        <box size="0.026 0.074 0.138"/>
      </geometry>
    </collision>
    <collision>
      <origin rpy="0 1.57079632679 0" xyz="-0.03 0 -0.315"/>
      <geometry>
        <cylinder length="0.018" radius="0.017"/>
      </geometry>
    </collision>
    <collision>
      <origin rpy="0 1.57079632679 0" xyz="0.036 0 -0.315"/>
      <geometry>
        <cylinder length="0.013" radius="0.017"/>
      </geometry>
    </collision>
    <inertial>
      <mass value="1.851"/>
      <origin rpy="0 0 0" xyz="-0.0418 0 -0.0517"/>
      <inertia ixx="0.0238" ixy="0" ixz="0" iyy="0.0252" iyz="0" izz="0.0044"/>
    </inertial>
  </link>
  <!-- pitch joint connects hip to upper leg -->
  <joint name="back_left_pitch_joint" type="revolute">
    <axis rpy="0 0 0" xyz="-1 0 0"/>
    <parent link="back_left_hip"/>
    <child link="back_left_upperleg"/>
    <origin rpy="0 0 0" xyz="-0.09875 0 0"/>
    <limit effort="60" lower="-1.57079632679" upper="3.14159265359" velocity="6.0"/>
  </joint>
  <link name="back_left_lowerleg">
    <visual>
      <origin rpy="-1.57079632679 0 0" xyz="0 0 0"/>
      <geometry>
        <mesh filename="package://dogbot_description/meshes/LegLower_nofoot.dae" scale="1.0 1.0 1.0"/>
      </geometry>
    </visual>
    <collision>
      <origin rpy="0 1.57079632679 0" xyz="0 0 0"/>
      <geometry>
        <cylinder length="0.033" radius="0.042"/>
      </geometry>
    </collision>
    <collision>
      <origin rpy="0 0 0" xyz="0.024 -0.0375 -0.0055"/>
      <geometry>
        <box size="0.02 0.017 0.065"/>
      </geometry>
    </collision>
    <collision>
      <origin rpy="0 0 0" xyz="-0.024 -0.0375 -0.0055"/>
      <geometry>
        <box size="0.02 0.017 0.065"/>
      </geometry>
    </collision>
    <collision>
      <origin rpy="0 0.04996 0" xyz="0.01575 -0.0375 -0.145"/>
      <geometry>
        <cylinder length="0.29" radius="0.006"/>
      </geometry>
    </collision>
    <collision>
      <origin rpy="0 -0.04996 0" xyz="-0.01575 -0.0375 -0.145"/>
      <geometry>
        <cylinder length="0.29" radius="0.006"/>
      </geometry>
    </collision>
    <inertial>
      <mass value="0.302"/>
      <origin rpy="0 0 0" xyz="0 -0.029 -0.1439"/>
      <inertia ixx="0.00527" ixy="0" ixz="0" iyy="0.00509" iyz="0" izz="0.0008"/>
    </inertial>
  </link>
  <gazebo reference="back_left_lowerleg">
    <mu1 value="2000.0"/>
    <mu2 value="1000.0"/>
    <kp value="1000000"/>
    <kd value="1.0"/>
    <selfCollide value="true"/>
  </gazebo>
  <joint name="back_left_knee_joint" type="revolute">
    <axis rpy="-6.28318530718 0 0" xyz="1 0 0"/>
    <parent link="back_left_upperleg"/>
    <child link="back_left_lowerleg"/>
    <origin rpy="0 0 0" xyz="0 0 -0.315"/>
    <limit effort="60" lower="-2.61795" upper="0.02" velocity="6.0"/>
  </joint>
  <link name="back_left_foot">
    <visual>
      <origin rpy="-1.57079632679 0 0" xyz="0 0 0"/>
      <geometry>
        <mesh filename="package://dogbot_description/meshes/foot.dae" scale="1.0 1.0 1.0"/>
      </geometry>
    </visual>
    <collision>
      <origin rpy="0 0 0" xyz="0 -0.035 -0.3"/>
      <geometry>
        <sphere radius="0.028"/>
      </geometry>
    </collision>
    <inertial>
      <mass value="0.001"/>
      <origin rpy="0 0 0" xyz="0 0 0"/>
      <inertia ixx="1.66666666667e-10" ixy="0.0" ixz="0.0" iyy="1.66666666667e-10" iyz="0.0" izz="1.66666666667e-10"/>
    </inertial>
  </link>
  <joint name="back_left_foot_joint" type="fixed">
    <axis rpy="0 0 0" xyz="0 1 0"/>
    <parent link="back_left_lowerleg"/>
    <child link="back_left_foot"/>
    <origin rpy="0 0 0" xyz="-2.059009593607686e-05 -0.016585135985853 -0.321099633029770"/>
  </joint>
  <gazebo reference="back_left_foot">
    <mu1 value="2000.0"/>
    <mu2 value="1000.0"/>
    <kp value="1000000"/>
    <kd value="1.0"/>
    <!-- Contact Sensor -->
    <sensor name="back_left_contactsensor_sensor" type="contact">
      <always_on>true</always_on>
      <contact>
        <collision>back_left_lowerleg_fixed_joint_lump__back_left_foot_collision_5</collision>
      </contact>
      <plugin filename="libgazebo_ros_bumper.so" name="back_left_foot_plugin">
        <bumperTopicName>back_left_contactsensor_state</bumperTopicName>
        <!--<frameName>${prefix}_${suffix}_foot</frameName>-->
        <frameName>world</frameName>
      </plugin>
    </sensor>
  </gazebo>
  <transmission name="back_left_roll_transmition">
    <type>transmission_interface/SimpleTransmission</type>
    <joint name="back_left_roll_joint">
      <hardwareInterface>hardware_interface/EffortJointInterface</hardwareInterface>
    </joint>
    <actuator name="back_left_roll_motor">
      <hardwareInterface>hardware_interface/EffortJointInterface</hardwareInterface>
      <mechanicalReduction>1</mechanicalReduction>
    </actuator>
  </transmission>
  <transmission name="back_left_pitch_transmition">
    <type>transmission_interface/SimpleTransmission</type>
    <joint name="back_left_pitch_joint">
      <hardwareInterface>hardware_interface/EffortJointInterface</hardwareInterface>
    </joint>
    <actuator name="back_left_pitch_motor">
      <hardwareInterface>hardware_interface/EffortJointInterface</hardwareInterface>
      <mechanicalReduction>1</mechanicalReduction>
    </actuator>
  </transmission>
  <transmission name="back_left_knee_transmition">
    <type>transmission_interface/SimpleTransmission</type>
    <joint name="back_left_knee_joint">
      <hardwareInterface>hardware_interface/EffortJointInterface</hardwareInterface>
    </joint>
    <actuator name="back_left_knee_motor">
      <hardwareInterface>hardware_interface/EffortJointInterface</hardwareInterface>
      <mechanicalReduction>1</mechanicalReduction>
    </actuator>
  </transmission>
  <link name="back_right_hip">
    <visual>
      <origin rpy="-1.57079632679 0.0 0" xyz="0 0 0"/>
      <geometry>
        <mesh filename="package://dogbot_description/meshes/hip.dae" scale="1.0 1.0 1.0"/>
      </geometry>
    </visual>
    <collision>
      <origin rpy="0 1.57079632679 0" xyz="0.02 0 0"/>
      <geometry>
        <cylinder length="0.08" radius="0.0525"/>
      </geometry>
    </collision>
    <inertial>
      <mass value="0.836"/>
      <origin rpy="0 0 0" xyz="0.0074 0 0"/>
      <inertia ixx="0.00213" ixy="0" ixz="0" iyy="0.00147" iyz="0" izz="0.00172"/>
    </inertial>
  </link>
  <!-- roll joint connects the hip to the body -->
  <joint name="back_right_roll_joint" type="revolute">
    <axis rpy="0 0 0" xyz="0 -1 0"/>
    <parent link="body"/>
    <child link="back_right_hip"/>
    <origin rpy="0 0 0" xyz="0.088 -0.2875 0"/>
    <limit effort="60" lower="-1.7453" upper="1.7453" velocity="6.0"/>
  </joint>
  <link name="back_right_upperleg">
    <visual>
      <origin rpy="-1.57079632679 0 0.0" xyz="0 0 0"/>
      <geometry>
        <mesh filename="package://dogbot_description/meshes/LegUpper_withCover.dae" scale="1.0 1.0 1.0"/>
      </geometry>
    </visual>
    <collision>
      <origin rpy="0 1.57079632679 0" xyz="0.03 0 0"/>
      <geometry>
        <cylinder length="0.13" radius="0.0525"/>
      </geometry>
    </collision>
    <collision>
      <origin rpy="0 0 0" xyz="0 0 -0.135"/>
      <geometry>
        <cylinder length="0.27" radius="0.033"/>
      </geometry>
    </collision>
    <collision>
      <origin rpy="0 0 0" xyz="0 0 -0.135"/>
      <geometry>
        <box size="0.025 0.084 0.27"/>
      </geometry>
    </collision>
    <collision>
      <origin rpy="0 0 0" xyz="0.046 0 -0.126"/>
      <geometry>
        <box size="0.026 0.074 0.138"/>
      </geometry>
    </collision>
    <collision>
      <origin rpy="0 1.57079632679 0" xyz="0.03 0 -0.315"/>
      <geometry>
        <cylinder length="0.018" radius="0.017"/>
      </geometry>
    </collision>
    <collision>
      <origin rpy="0 1.57079632679 0" xyz="-0.036 0 -0.315"/>
      <geometry>
        <cylinder length="0.013" radius="0.017"/>
      </geometry>
    </collision>
    <inertial>
      <mass value="1.851"/>
      <origin rpy="0 0 0" xyz="0.0418 0 -0.0517"/>
      <inertia ixx="0.0238" ixy="0" ixz="0" iyy="0.0252" iyz="0" izz="0.0044"/>
    </inertial>
  </link>
  <!-- pitch joint connects hip to upper leg -->
  <joint name="back_right_pitch_joint" type="revolute">
    <axis rpy="0 0 0" xyz="1 0 0"/>
    <parent link="back_right_hip"/>
    <child link="back_right_upperleg"/>
    <origin rpy="0 0 0" xyz="0.09875 0 0"/>
    <limit effort="60" lower="-3.14159265359" upper="1.57079632679" velocity="6.0"/>
  </joint>
  <link name="back_right_lowerleg">
    <visual>
      <origin rpy="-1.57079632679 0 0" xyz="0 0 0"/>
      <geometry>
        <mesh filename="package://dogbot_description/meshes/LegLower_nofoot.dae" scale="1.0 1.0 1.0"/>
      </geometry>
    </visual>
    <collision>
      <origin rpy="0 1.57079632679 0" xyz="0 0 0"/>
      <geometry>
        <cylinder length="0.033" radius="0.042"/>
      </geometry>
    </collision>
    <collision>
      <origin rpy="0 0 0" xyz="0.024 -0.0375 -0.0055"/>
      <geometry>
        <box size="0.02 0.017 0.065"/>
      </geometry>
    </collision>
    <collision>
      <origin rpy="0 0 0" xyz="-0.024 -0.0375 -0.0055"/>
      <geometry>
        <box size="0.02 0.017 0.065"/>
      </geometry>
    </collision>
    <collision>
      <origin rpy="0 0.04996 0" xyz="0.01575 -0.0375 -0.145"/>
      <geometry>
        <cylinder length="0.29" radius="0.006"/>
      </geometry>
    </collision>
    <collision>
      <origin rpy="0 -0.04996 0" xyz="-0.01575 -0.0375 -0.145"/>
      <geometry>
        <cylinder length="0.29" radius="0.006"/>
      </geometry>
    </collision>
    <inertial>
      <mass value="0.302"/>
      <origin rpy="0 0 0" xyz="0 -0.029 -0.1439"/>
      <inertia ixx="0.00527" ixy="0" ixz="0" iyy="0.00509" iyz="0" izz="0.0008"/>
    </inertial>
  </link>
  <gazebo reference="back_right_lowerleg">
    <mu1 value="2000.0"/>
    <mu2 value="1000.0"/>
    <kp value="1000000"/>
    <kd value="1.0"/>
    <selfCollide value="true"/>
  </gazebo>
  <joint name="back_right_knee_joint" type="revolute">
    <axis rpy="-6.28318530718 0 0" xyz="-1 0 0"/>
    <parent link="back_right_upperleg"/>
    <child link="back_right_lowerleg"/>
    <origin rpy="0 0 0" xyz="0 0 -0.315"/>
    <limit effort="60" lower="-0.02" upper="2.61795" velocity="6.0"/>
  </joint>
  <link name="back_right_foot">
    <visual>
      <origin rpy="-1.57079632679 0 0" xyz="0 0 0"/>
      <geometry>
        <mesh filename="package://dogbot_description/meshes/foot.dae" scale="1.0 1.0 1.0"/>
      </geometry>
    </visual>
    <collision>
      <origin rpy="0 0 0" xyz="0 -0.035 -0.3"/>
      <geometry>
        <sphere radius="0.028"/>
      </geometry>
    </collision>
    <inertial>
      <mass value="0.001"/>
      <origin rpy="0 0 0" xyz="0 0 0"/>
      <inertia ixx="1.66666666667e-10" ixy="0.0" ixz="0.0" iyy="1.66666666667e-10" iyz="0.0" izz="1.66666666667e-10"/>
    </inertial>
  </link>
  <joint name="back_right_foot_joint" type="fixed">
    <axis rpy="0 0 0" xyz="0 1 0"/>
    <parent link="back_right_lowerleg"/>
    <child link="back_right_foot"/>
    <origin rpy="0 0 0" xyz="-2.059009593607686e-05 -0.016585135985853 -0.321099633029770"/>
  </joint>
  <gazebo reference="back_right_foot">
    <mu1 value="2000.0"/>
    <mu2 value="1000.0"/>
    <kp value="1000000"/>
    <kd value="1.0"/>
    <!-- Contact Sensor -->
    <sensor name="back_right_contactsensor_sensor" type="contact">
      <always_on>true</always_on>
      <contact>
        <collision>back_right_lowerleg_fixed_joint_lump__back_right_foot_collision_5</collision>
      </contact>
      <plugin filename="libgazebo_ros_bumper.so" name="back_right_foot_plugin">
        <bumperTopicName>back_right_contactsensor_state</bumperTopicName>
        <!--<frameName>${prefix}_${suffix}_foot</frameName>-->
        <frameName>world</frameName>
      </plugin>
    </sensor>
  </gazebo>
  <transmission name="back_right_roll_transmition">
    <type>transmission_interface/SimpleTransmission</type>
    <joint name="back_right_roll_joint">
      <hardwareInterface>hardware_interface/EffortJointInterface</hardwareInterface>
    </joint>
    <actuator name="back_right_roll_motor">
      <hardwareInterface>hardware_interface/EffortJointInterface</hardwareInterface>
      <mechanicalReduction>1</mechanicalReduction>
    </actuator>
  </transmission>
  <transmission name="back_right_pitch_transmition">
    <type>transmission_interface/SimpleTransmission</type>
    <joint name="back_right_pitch_joint">
      <hardwareInterface>hardware_interface/EffortJointInterface</hardwareInterface>
    </joint>
    <actuator name="back_right_pitch_motor">
      <hardwareInterface>hardware_interface/EffortJointInterface</hardwareInterface>
      <mechanicalReduction>1</mechanicalReduction>
    </actuator>
  </transmission>
  <transmission name="back_right_knee_transmition">
    <type>transmission_interface/SimpleTransmission</type>
    <joint name="back_right_knee_joint">
      <hardwareInterface>hardware_interface/EffortJointInterface</hardwareInterface>
    </joint>
    <actuator name="back_right_knee_motor">
      <hardwareInterface>hardware_interface/EffortJointInterface</hardwareInterface>
      <mechanicalReduction>1</mechanicalReduction>
    </actuator>
  </transmission>
  <link name="front_left_hip">
    <visual>
      <origin rpy="-1.57079632679 -3.14159265359 0" xyz="0 0 0"/>
      <geometry>
        <mesh filename="package://dogbot_description/meshes/hip.dae" scale="1.0 1.0 1.0"/>
      </geometry>
    </visual>
    <collision>
      <origin rpy="0 1.57079632679 0" xyz="-0.02 0 0"/>
      <geometry>
        <cylinder length="0.08" radius="0.0525"/>
      </geometry>
    </collision>
    <inertial>
      <mass value="0.836"/>
      <origin rpy="0 0 0" xyz="-0.0074 0 0"/>
      <inertia ixx="0.00213" ixy="0" ixz="0" iyy="0.00147" iyz="0" izz="0.00172"/>
    </inertial>
  </link>
  <!-- roll joint connects the hip to the body -->
  <joint name="front_left_roll_joint" type="revolute">
    <axis rpy="0 0 0" xyz="0 1 0"/>
    <parent link="body"/>
    <child link="front_left_hip"/>
    <origin rpy="0 0 0" xyz="-0.088 0.2875 0"/>
    <limit effort="60" lower="-1.7453" upper="1.7453" velocity="6.0"/>
  </joint>
  <link name="front_left_upperleg">
    <visual>
      <origin rpy="-1.57079632679 0 -3.14159265359" xyz="0 0 0"/>
      <geometry>
        <mesh filename="package://dogbot_description/meshes/LegUpper_withCover.dae" scale="1.0 1.0 1.0"/>
      </geometry>
    </visual>
    <collision>
      <origin rpy="0 1.57079632679 0" xyz="-0.03 0 0"/>
      <geometry>
        <cylinder length="0.13" radius="0.0525"/>
      </geometry>
    </collision>
    <collision>
      <origin rpy="0 0 0" xyz="0 0 -0.135"/>
      <geometry>
        <cylinder length="0.27" radius="0.033"/>
      </geometry>
    </collision>
    <collision>
      <origin rpy="0 0 0" xyz="0 0 -0.135"/>
      <geometry>
        <box size="0.025 0.084 0.27"/>
      </geometry>
    </collision>
    <collision>
      <origin rpy="0 0 0" xyz="-0.046 0 -0.126"/>
      <geometry>
        <box size="0.026 0.074 0.138"/>
      </geometry>
    </collision>
    <collision>
      <origin rpy="0 1.57079632679 0" xyz="-0.03 0 -0.315"/>
      <geometry>
        <cylinder length="0.018" radius="0.017"/>
      </geometry>
    </collision>
    <collision>
      <origin rpy="0 1.57079632679 0" xyz="0.036 0 -0.315"/>
      <geometry>
        <cylinder length="0.013" radius="0.017"/>
      </geometry>
    </collision>
    <inertial>
      <mass value="1.851"/>
      <origin rpy="0 0 0" xyz="-0.0418 0 -0.0517"/>
      <inertia ixx="0.0238" ixy="0" ixz="0" iyy="0.0252" iyz="0" izz="0.0044"/>
    </inertial>
  </link>
  <!-- pitch joint connects hip to upper leg -->
  <joint name="front_left_pitch_joint" type="revolute">
    <axis rpy="0 0 0" xyz="-1 0 0"/>
    <parent link="front_left_hip"/>
    <child link="front_left_upperleg"/>
    <origin rpy="0 0 0" xyz="-0.09875 0 0"/>
    <limit effort="60" lower="-1.57079632679" upper="3.14159265359" velocity="6.0"/>
  </joint>
  <link name="front_left_lowerleg">
    <visual>
      <origin rpy="-1.57079632679 0 0" xyz="0 0 0"/>
      <geometry>
        <mesh filename="package://dogbot_description/meshes/LegLower_nofoot.dae" scale="1.0 1.0 1.0"/>
      </geometry>
    </visual>
    <collision>
      <origin rpy="0 1.57079632679 0" xyz="0 0 0"/>
      <geometry>
        <cylinder length="0.033" radius="0.042"/>
      </geometry>
    </collision>
    <collision>
      <origin rpy="0 0 0" xyz="0.024 -0.0375 -0.0055"/>
      <geometry>
        <box size="0.02 0.017 0.065"/>
      </geometry>
    </collision>
    <collision>
      <origin rpy="0 0 0" xyz="-0.024 -0.0375 -0.0055"/>
      <geometry>
        <box size="0.02 0.017 0.065"/>
      </geometry>
    </collision>
    <collision>
      <origin rpy="0 0.04996 0" xyz="0.01575 -0.0375 -0.145"/>
      <geometry>
        <cylinder length="0.29" radius="0.006"/>
      </geometry>
    </collision>
    <collision>
      <origin rpy="0 -0.04996 0" xyz="-0.01575 -0.0375 -0.145"/>
      <geometry>
        <cylinder length="0.29" radius="0.006"/>
      </geometry>
    </collision>
    <inertial>
      <mass value="0.302"/>
      <origin rpy="0 0 0" xyz="0 -0.029 -0.1439"/>
      <inertia ixx="0.00527" ixy="0" ixz="0" iyy="0.00509" iyz="0" izz="0.0008"/>
    </inertial>
  </link>
  <gazebo reference="front_left_lowerleg">
    <mu1 value="2000.0"/>
    <mu2 value="1000.0"/>
    <kp value="1000000"/>
    <kd value="1.0"/>
    <selfCollide value="true"/>
  </gazebo>
  <joint name="front_left_knee_joint" type="revolute">
    <axis rpy="-6.28318530718 0 0" xyz="1 0 0"/>
    <parent link="front_left_upperleg"/>
    <child link="front_left_lowerleg"/>
    <origin rpy="0 0 0" xyz="0 0 -0.315"/>
    <limit effort="60" lower="-2.61795" upper="0.02" velocity="6.0"/>
  </joint>
  <link name="front_left_foot">
    <visual>
      <origin rpy="-1.57079632679 0 0" xyz="0 0 0"/>
      <geometry>
        <mesh filename="package://dogbot_description/meshes/foot.dae" scale="1.0 1.0 1.0"/>
      </geometry>
    </visual>
    <collision>
      <origin rpy="0 0 0" xyz="0 -0.035 -0.3"/>
      <geometry>
        <sphere radius="0.028"/>
      </geometry>
    </collision>
    <inertial>
      <mass value="0.001"/>
      <origin rpy="0 0 0" xyz="0 0 0"/>
      <inertia ixx="1.66666666667e-10" ixy="0.0" ixz="0.0" iyy="1.66666666667e-10" iyz="0.0" izz="1.66666666667e-10"/>
    </inertial>
  </link>
  <joint name="front_left_foot_joint" type="fixed">
    <axis rpy="0 0 0" xyz="0 1 0"/>
    <parent link="front_left_lowerleg"/>
    <child link="front_left_foot"/>
    <origin rpy="0 0 0" xyz="-2.059009593607686e-05 -0.016585135985853 -0.321099633029770"/>
  </joint>
  <gazebo reference="front_left_foot">
    <mu1 value="2000.0"/>
    <mu2 value="1000.0"/>
    <kp value="1000000"/>
    <kd value="1.0"/>
    <!-- Contact Sensor -->
    <sensor name="front_left_contactsensor_sensor" type="contact">
      <always_on>true</always_on>
      <contact>
        <collision>front_left_lowerleg_fixed_joint_lump__front_left_foot_collision_5</collision>
      </contact>
      <plugin filename="libgazebo_ros_bumper.so" name="front_left_foot_plugin">
        <bumperTopicName>front_left_contactsensor_state</bumperTopicName>
        <!--<frameName>${prefix}_${suffix}_foot</frameName>-->
        <frameName>world</frameName>
      </plugin>
    </sensor>
  </gazebo>
  <transmission name="front_left_roll_transmition">
    <type>transmission_interface/SimpleTransmission</type>
    <joint name="front_left_roll_joint">
      <hardwareInterface>hardware_interface/EffortJointInterface</hardwareInterface>
    </joint>
    <actuator name="front_left_roll_motor">
      <hardwareInterface>hardware_interface/EffortJointInterface</hardwareInterface>
      <mechanicalReduction>1</mechanicalReduction>
    </actuator>
  </transmission>
  <transmission name="front_left_pitch_transmition">
    <type>transmission_interface/SimpleTransmission</type>
    <joint name="front_left_pitch_joint">
      <hardwareInterface>hardware_interface/EffortJointInterface</hardwareInterface>
    </joint>
    <actuator name="front_left_pitch_motor">
      <hardwareInterface>hardware_interface/EffortJointInterface</hardwareInterface>
      <mechanicalReduction>1</mechanicalReduction>
    </actuator>
  </transmission>
  <transmission name="front_left_knee_transmition">
    <type>transmission_interface/SimpleTransmission</type>
    <joint name="front_left_knee_joint">
      <hardwareInterface>hardware_interface/EffortJointInterface</hardwareInterface>
    </joint>
    <actuator name="front_left_knee_motor">
      <hardwareInterface>hardware_interface/EffortJointInterface</hardwareInterface>
      <mechanicalReduction>1</mechanicalReduction>
    </actuator>
  </transmission>
  <link name="front_right_hip">
    <visual>
      <origin rpy="-1.57079632679 0.0 0" xyz="0 0 0"/>
      <geometry>
        <mesh filename="package://dogbot_description/meshes/hip.dae" scale="1.0 1.0 1.0"/>
      </geometry>
    </visual>
    <collision>
      <origin rpy="0 1.57079632679 0" xyz="0.02 0 0"/>
      <geometry>
        <cylinder length="0.08" radius="0.0525"/>
      </geometry>
    </collision>
    <inertial>
      <mass value="0.836"/>
      <origin rpy="0 0 0" xyz="0.0074 0 0"/>
      <inertia ixx="0.00213" ixy="0" ixz="0" iyy="0.00147" iyz="0" izz="0.00172"/>
    </inertial>
  </link>
  <!-- roll joint connects the hip to the body -->
  <joint name="front_right_roll_joint" type="revolute">
    <axis rpy="0 0 0" xyz="0 1 0"/>
    <parent link="body"/>
    <child link="front_right_hip"/>
    <origin rpy="0 0 0" xyz="0.088 0.2875 0"/>
    <limit effort="60" lower="-1.7453" upper="1.7453" velocity="6.0"/>
  </joint>
  <link name="front_right_upperleg">
    <visual>
      <origin rpy="-1.57079632679 0 0.0" xyz="0 0 0"/>
      <geometry>
        <mesh filename="package://dogbot_description/meshes/LegUpper_withCover.dae" scale="1.0 1.0 1.0"/>
      </geometry>
    </visual>
    <collision>
      <origin rpy="0 1.57079632679 0" xyz="0.03 0 0"/>
      <geometry>
        <cylinder length="0.13" radius="0.0525"/>
      </geometry>
    </collision>
    <collision>
      <origin rpy="0 0 0" xyz="0 0 -0.135"/>
      <geometry>
        <cylinder length="0.27" radius="0.033"/>
      </geometry>
    </collision>
    <collision>
      <origin rpy="0 0 0" xyz="0 0 -0.135"/>
      <geometry>
        <box size="0.025 0.084 0.27"/>
      </geometry>
    </collision>
    <collision>
      <origin rpy="0 0 0" xyz="0.046 0 -0.126"/>
      <geometry>
        <box size="0.026 0.074 0.138"/>
      </geometry>
    </collision>
    <collision>
      <origin rpy="0 1.57079632679 0" xyz="0.03 0 -0.315"/>
      <geometry>
        <cylinder length="0.018" radius="0.017"/>
      </geometry>
    </collision>
    <collision>
      <origin rpy="0 1.57079632679 0" xyz="-0.036 0 -0.315"/>
      <geometry>
        <cylinder length="0.013" radius="0.017"/>
      </geometry>
    </collision>
    <inertial>
      <mass value="1.851"/>
      <origin rpy="0 0 0" xyz="0.0418 0 -0.0517"/>
      <inertia ixx="0.0238" ixy="0" ixz="0" iyy="0.0252" iyz="0" izz="0.0044"/>
    </inertial>
  </link>
  <!-- pitch joint connects hip to upper leg -->
  <joint name="front_right_pitch_joint" type="revolute">
    <axis rpy="0 0 0" xyz="1 0 0"/>
    <parent link="front_right_hip"/>
    <child link="front_right_upperleg"/>
    <origin rpy="0 0 0" xyz="0.09875 0 0"/>
    <limit effort="60" lower="-3.14159265359" upper="1.57079632679" velocity="6.0"/>
  </joint>
  <link name="front_right_lowerleg">
    <visual>
      <origin rpy="-1.57079632679 0 0" xyz="0 0 0"/>
      <geometry>
        <mesh filename="package://dogbot_description/meshes/LegLower_nofoot.dae" scale="1.0 1.0 1.0"/>
      </geometry>
    </visual>
    <collision>
      <origin rpy="0 1.57079632679 0" xyz="0 0 0"/>
      <geometry>
        <cylinder length="0.033" radius="0.042"/>
      </geometry>
    </collision>
    <collision>
      <origin rpy="0 0 0" xyz="0.024 -0.0375 -0.0055"/>
      <geometry>
        <box size="0.02 0.017 0.065"/>
      </geometry>
    </collision>
    <collision>
      <origin rpy="0 0 0" xyz="-0.024 -0.0375 -0.0055"/>
      <geometry>
        <box size="0.02 0.017 0.065"/>
      </geometry>
    </collision>
    <collision>
      <origin rpy="0 0.04996 0" xyz="0.01575 -0.0375 -0.145"/>
      <geometry>
        <cylinder length="0.29" radius="0.006"/>
      </geometry>
    </collision>
    <collision>
      <origin rpy="0 -0.04996 0" xyz="-0.01575 -0.0375 -0.145"/>
      <geometry>
        <cylinder length="0.29" radius="0.006"/>
      </geometry>
    </collision>
    <inertial>
      <mass value="0.302"/>
      <origin rpy="0 0 0" xyz="0 -0.029 -0.1439"/>
      <inertia ixx="0.00527" ixy="0" ixz="0" iyy="0.00509" iyz="0" izz="0.0008"/>
    </inertial>
  </link>
  <gazebo reference="front_right_lowerleg">
    <mu1 value="2000.0"/>
    <mu2 value="1000.0"/>
    <kp value="1000000"/>
    <kd value="1.0"/>
    <selfCollide value="true"/>
  </gazebo>
  <joint name="front_right_knee_joint" type="revolute">
    <axis rpy="-6.28318530718 0 0" xyz="-1 0 0"/>
    <parent link="front_right_upperleg"/>
    <child link="front_right_lowerleg"/>
    <origin rpy="0 0 0" xyz="0 0 -0.315"/>
    <limit effort="60" lower="-0.02" upper="2.61795" velocity="6.0"/>
  </joint>
  <link name="front_right_foot">
    <visual>
      <origin rpy="-1.57079632679 0 0" xyz="0 0 0"/>
      <geometry>
        <mesh filename="package://dogbot_description/meshes/foot.dae" scale="1.0 1.0 1.0"/>
      </geometry>
    </visual>
    <collision>
      <origin rpy="0 0 0" xyz="0 -0.035 -0.3"/>
      <geometry>
        <sphere radius="0.028"/>
      </geometry>
    </collision>
    <inertial>
      <mass value="0.001"/>
      <origin rpy="0 0 0" xyz="0 0 0"/>
      <inertia ixx="1.66666666667e-10" ixy="0.0" ixz="0.0" iyy="1.66666666667e-10" iyz="0.0" izz="1.66666666667e-10"/>
    </inertial>
  </link>
  <joint name="front_right_foot_joint" type="fixed">
    <axis rpy="0 0 0" xyz="0 1 0"/>
    <parent link="front_right_lowerleg"/>
    <child link="front_right_foot"/>
    <origin rpy="0 0 0" xyz="-2.059009593607686e-05 -0.016585135985853 -0.321099633029770"/>
  </joint>
  <gazebo reference="front_right_foot">
    <mu1 value="2000.0"/>
    <mu2 value="1000.0"/>
    <kp value="1000000"/>
    <kd value="1.0"/>
    <!-- Contact Sensor -->
    <sensor name="front_right_contactsensor_sensor" type="contact">
      <always_on>true</always_on>
      <contact>
        <collision>front_right_lowerleg_fixed_joint_lump__front_right_foot_collision_5</collision>
      </contact>
      <plugin filename="libgazebo_ros_bumper.so" name="front_right_foot_plugin">
        <bumperTopicName>front_right_contactsensor_state</bumperTopicName>
        <!--<frameName>${prefix}_${suffix}_foot</frameName>-->
        <frameName>world</frameName>
      </plugin>
    </sensor>
  </gazebo>
  <transmission name="front_right_roll_transmition">
    <type>transmission_interface/SimpleTransmission</type>
    <joint name="front_right_roll_joint">
      <hardwareInterface>hardware_interface/EffortJointInterface</hardwareInterface>
    </joint>
    <actuator name="front_right_roll_motor">
      <hardwareInterface>hardware_interface/EffortJointInterface</hardwareInterface>
      <mechanicalReduction>1</mechanicalReduction>
    </actuator>
  </transmission>
  <transmission name="front_right_pitch_transmition">
    <type>transmission_interface/SimpleTransmission</type>
    <joint name="front_right_pitch_joint">
      <hardwareInterface>hardware_interface/EffortJointInterface</hardwareInterface>
    </joint>
    <actuator name="front_right_pitch_motor">
      <hardwareInterface>hardware_interface/EffortJointInterface</hardwareInterface>
      <mechanicalReduction>1</mechanicalReduction>
    </actuator>
  </transmission>
  <transmission name="front_right_knee_transmition">
    <type>transmission_interface/SimpleTransmission</type>
    <joint name="front_right_knee_joint">
      <hardwareInterface>hardware_interface/EffortJointInterface</hardwareInterface>
    </joint>
    <actuator name="front_right_knee_motor">
      <hardwareInterface>hardware_interface/EffortJointInterface</hardwareInterface>
      <mechanicalReduction>1</mechanicalReduction>
    </actuator>
  </transmission>
  <gazebo>
    <plugin filename="libhector_gazebo_ros_imu.so" name="imu_plugin">
      <alwaysOn>true</alwaysOn>
      <bodyName>body</bodyName>
      <robotNamespace>dogbot</robotNamespace>
      <topicName>imu</topicName>
      <serviceName>imu_service</serviceName>
      <gaussianNoise>0.0</gaussianNoise>
      <updateRate>20.0</updateRate>
    </plugin>
    <plugin filename="libhector_gazebo_ros_gps.so" name="gps_plugin">
      <alwaysOn>true</alwaysOn>
      <bodyName>body</bodyName>
      <robotNamespace>dogbot</robotNamespace>
      <topicName>gps</topicName>
      <serviceName>imu_service</serviceName>
      <updateRate>100</updateRate>
      <referenceLatitude>51.5</referenceLatitude>
      <referenceLongitude>0.1278</referenceLongitude>
    </plugin>
  </gazebo>
  <!-- Gazebo plugin for ROS Control -->
  <gazebo>
    <plugin filename="libgazebo_ros_control.so" name="gazebo_ros_control">
      <robotNamespace>/dogbot</robotNamespace>
    </plugin>
  </gazebo>
</robot>
